package main

import (
	"errors"
	"fmt"
	"time"
)

// начало решения

// ErrFailed и ErrManual - причины остановки цикла.
var ErrFailed = errors.New("failed")
var ErrManual = errors.New("manual")

// Worker выполняет заданную функцию в цикле, пока не будет остановлен.
// Гарантируется, что Worker используется только в одной горутине.
type Worker struct {
	fn      func() error
	started bool
	stopCh  chan struct{}
	doneCh  chan struct{}
	err     error
	after   []func()
}

// NewWorker создает новый экземпляр Worker с заданной функцией.
// Но пока не запускает цикл с функцией.
func NewWorker(fn func() error) *Worker {
	return &Worker{fn: fn}
}

// Start запускает отдельную горутину, в которой циклически
// выполняет заданную функцию, пока не будет вызван метод Stop,
// либо пока функция не вернет ошибку.
// Повторные вызовы Start игнорируются.
func (w *Worker) Start() {
	// TODO: реализовать требования
	if w.started == true {
		return
	}
	w.started = true
	w.stopCh = make(chan struct{})
	w.doneCh = make(chan struct{})
	after := append([]func(){}, w.after...)
	go func() {
		defer close(w.doneCh)
		for {
			select {
			case <-w.stopCh:
				w.err = ErrManual
				for _, f := range after {
					f()
				}
				return
			default:
				if e := w.fn(); e != nil {
					w.err = ErrFailed
					for _, f := range after {
						f()
					}
					return
				}
			}
		}
	}()
}

// Stop останавливает выполнение цикла.
// Вызов Stop до Start игнорируется.
// Повторные вызовы Stop игнорируются.
func (w *Worker) Stop() {
	// TODO: реализовать требования
	if !w.started {
		return
	}
	select {
	case <-w.stopCh:
	default:
		close(w.stopCh)
	}
	<-w.doneCh
}

// AfterStop регистрирует функцию, которая
// будет вызвана после остановки цикла.
// Можно зарегистрировать несколько функций.
// Вызовы AfterStop после Start игнорируются.
func (w *Worker) AfterStop(fn func()) {
	// TODO: реализовать требования
	if w.started == true {
		return
	}
	w.after = append(w.after, fn)
}

// Err возвращает причину остановки цикла:
// - ErrManual - вручную через метод Stop;
// - ErrFailed - из-за ошибки, которую вернула функция.
func (w *Worker) Err() error {
	// TODO: реализовать требования
	return w.err
}

// конец решения

func main() {
	{
		// Start-Stop
		count := 9
		fn := func() error {
			fmt.Print(count, " ")
			count--
			time.Sleep(10 * time.Millisecond)
			return nil
		}

		worker := NewWorker(fn)
		worker.Start()
		time.Sleep(105 * time.Millisecond)
		worker.Stop()

		fmt.Println()
		// 9 8 7 6 5 4 3 2 1 0
	}
	{
		// ErrFailed
		count := 3
		fn := func() error {
			fmt.Print(count, " ")
			count--
			if count == 0 {
				return errors.New("count is zero")
			}
			time.Sleep(10 * time.Millisecond)
			return nil
		}

		worker := NewWorker(fn)
		worker.Start()
		time.Sleep(35 * time.Millisecond)
		worker.Stop()

		fmt.Println(worker.Err())
		// 3 2 1 failed
	}
	{
		// AfterStop
		fn := func() error { return nil }

		worker := NewWorker(fn)
		worker.AfterStop(func() {
			fmt.Println("called after stop")
		})

		worker.Start()
		worker.Stop()

		time.Sleep(10 * time.Millisecond)
		// called after stop
	}
}
